Workbook

Sheet Cleaned_Orders
A1: order_id | B1: order_date | C1: ship_date | D1: customer_id | E1: customer_name | F1: segment | G1: region | H1: state | I1: city | J1: category | K1: sub_category | L1: product_name | M1: ship_mode | N1: quantity | O1: unit_price | P1: discount | Q1: sales | R1: cost | S1: profit | T1: payment_status | U1: order_status | V1: cleaned_discount | W1: calculated_sales | X1: calculated_profit | Y1: profit_margin | Z1: shipping_delay_days | AA1: order_month | AB1: order_year | AC1: original_data_flags | AD1: flag_details | AE1: data_quality_flag
A2: ORD-2024-10001 | B2: 45494 | C2: 45500 | D2: CUST-4655 | E2: =PROPER(TRIM(SUBSTITUTE(Raw_Text_Fields!B3,CHAR(160)," "))) -> Karan Malhotra | F2: =PROPER(TRIM(SUBSTITUTE(Raw_Text_Fields!C3,CHAR(160)," "))) -> Consumer | G2: =PROPER(TRIM(SUBSTITUTE(Raw_Text_Fields!D3,CHAR(160)," "))) -> North | H2: =PROPER(TRIM(SUBSTITUTE(Raw_Text_Fields!E3,CHAR(160)," "))) -> Rajasthan | I2: =PROPER(TRIM(SUBSTITUTE(Raw_Text_Fields!F3,CHAR(160)," "))) -> Jaipur | J2: =PROPER(TRIM(SUBSTITUTE(Raw_Text_Fields!G3,CHAR(160)," "))) -> Office Supplies | K2: =PROPER(TRIM(SUBSTITUTE(Raw_Text_Fields!H3,CHAR(160)," "))) -> Paper | L2: Pro Paper 122 | M2: =PROPER(TRIM(SUBSTITUTE(Raw_Text_Fields!I3,CHAR(160)," "))) -> Second Class | N2: 8 | O2: 2976.45 | P2: 0.2 | Q2: 19049.28 | R2: 15841.89 | S2: 3207.39 | T2: =PROPER(TRIM(SUBSTITUTE(Raw_Text_Fields!J3,CHAR(160)," "))) -> Paid | U2: =PROPER(TRIM(SUBSTITUTE(Raw_Text_Fields!K3,CHAR(160)," "))) -> Completed | V2: =IF(OR(P2<0,P2>0.5),0,P2) -> 0.2 | W2: =N2*O2*(1-V2) -> 19049.28 | X2: =W2-R2 -> 3207.39 | Y2: =IFERROR(X2/W2,0) -> 0.16837329 | Z2: =C2-B2 -> 6 | AA2: =IF(B2="","",TEXT(B2,"mmm")) -> Jul | AB2: =IF(B2="","",YEAR(B2)) -> 2024 | AD2: =IF(LEFT(AC2&IF(B2="","; Missing Order Date","")&IF(C2="","; Missing Ship Date","")&IF(P2<0,"; Invalid Discount (Negative)","")&IF(P2>0.5,"; Invalid Discount (Too High)","")&IF(Z2<0,"; Invalid Shipping Record (Ship Before Order)","")&IF(ABS(Q2-W2)>1,"; Sales Mismatch","")&IF(ABS(S2-X2)>1,"; Profit Mismatch","")&IF(COUNTIF($A$2:$A$913,A2)>1,"; Duplicate Order ID Conflict",""),2)="; ",MID(AC2&IF(B2="","; Missing Order Date","")&IF(C2="","; Missing Ship Date","")&IF(P2<0,"; Invalid Discount (Negative)","")&IF(P2>0.5,"; Invalid Discount (Too High)","")&IF(Z2<0,"; Invalid Shipping Record (Ship Before Order)","")&IF(ABS(Q2-W2)>1,"; Sales Mismatch","")&IF(ABS(S2-X2)>1,"; Profit Mismatch","")&IF(COUNTIF($A$2:$A$913,A2)>1,"; Duplicate Order ID Conflict",""),3,500),AC2&IF(B2="","; Missing Order Date","")&IF(C2="","; Missing Ship Date","")&IF(P2<0,"; Invalid Discount (Negative)","")&IF(P2>0.5,"; Invalid Discount (Too High)","")&IF(Z2<0,"; Invalid Shipping Record (Ship Before Order)","")&IF(ABS(Q2-W2)>1,"; Sales Mismatch","")&IF(ABS(S2-X2)>1,"; Profit Mismatch","")&IF(COUNTIF($A$2:$A$913,A2)>1,"; Duplicate Order ID Conflict","")) | AE2: =IF(OR(ISNUMBER(SEARCH("Invalid Discount",AD2)),ISNUMBER(SEARCH("Invalid Shipping Record",AD2)),ISNUMBER(SEARCH("Sales Mismatch",AD2)),ISNUMBER(SEARCH("Profit Mismatch",AD2)),ISNUMBER(SEARCH("Duplicate Order ID Conflict",AD2)),ISNUMBER(SEARCH("Missing Order Date",AD2)),ISNUMBER(SEARCH("Missing Ship Date",AD2))),"Invalid",IF(AD2<>"","Warning","Clean")) -> Clean
A3: ORD-2024-10002 | B3: 45535 | C3: 45540 | D3: CUST-2054 | E3: =PROPER(TRIM(SUBSTITUTE(Raw_Text_Fields!B4,CHAR(160)," "))) -> Mira Das | F3: =PROPER(TRIM(SUBSTITUTE(Raw_Text_Fields!C4,CHAR(160)," "))) -> Small Business | G3: =PROPER(TRIM(SUBSTITUTE(Raw_Text_Fields!D4,CHAR(160)," "))) -> East | H3: =PROPER(TRIM(SUBSTITUTE(Raw_Text_Fields!E4,CHAR(160)," "))) -> Odisha | I3: =PROPER(TRIM(SUBSTITUTE(Raw_Text_Fields!F4,CHAR(160)," "))) -> Bhubaneswar | J3: =PROPER(TRIM(SUBSTITUTE(Raw_Text_Fields!G4,CHAR(160)," "))) -> Furniture | K3: =PROPER(TRIM(SUBSTITUTE(Raw_Text_Fields!H4,CHAR(160)," "))) -> Tables | L3: Pro Tables 258 | M3: =PROPER(TRIM(SUBSTITUTE(Raw_Text_Fields!I4,CHAR(160)," "))) -> Same Day | N3: 3 | O3: 2437.5 | P3: 0 | Q3: 7312.5 | R3: 4904.73 | S3: 2407.77 | T3: =PROPER(TRIM(SUBSTITUTE(Raw_Text_Fields!J4,CHAR(160)," "))) -> Paid | U3: =PROPER(TRIM(SUBSTITUTE(Raw_Text_Fields!K4,CHAR(160)," "))) -> Completed | V3: =IF(OR(P3<0,P3>0.5),0,P3) -> 0 | W3: =N3*O3*(1-V3) -> 7312.5 | X3: =W3-R3 -> 2407.77 | Y3: =IFERROR(X3/W3,0) -> 0.32926769 | Z3: =C3-B3 -> 5 | AA3: =IF(B3="","",TEXT(B3,"mmm")) -> Aug | AB3: =IF(B3="","",YEAR(B3)) -> 2024 | AD3: =IF(LEFT(AC3&IF(B3="","; Missing Order Date","")&IF(C3="","; Missing Ship Date","")&IF(P3<0,"; Invalid Discount (Negative)","")&IF(P3>0.5,"; Invalid Discount (Too High)","")&IF(Z3<0,"; Invalid Shipping Record (Ship Before Order)","")&IF(ABS(Q3-W3)>1,"; Sales Mismatch","")&IF(ABS(S3-X3)>1,"; Profit Mismatch","")&IF(COUNTIF($A$2:$A$913,A3)>1,"; Duplicate Order ID Conflict",""),2)="; ",MID(AC3&IF(B3="","; Missing Order Date","")&IF(C3="","; Missing Ship Date","")&IF(P3<0,"; Invalid Discount (Negative)","")&IF(P3>0.5,"; Invalid Discount (Too High)","")&IF(Z3<0,"; Invalid Shipping Record (Ship Before Order)","")&IF(ABS(Q3-W3)>1,"; Sales Mismatch","")&IF(ABS(S3-X3)>1,"; Profit Mismatch","")&IF(COUNTIF($A$2:$A$913,A3)>1,"; Duplicate Order ID Conflict",""),3,500),AC3&IF(B3="","; Missing Order Date","")&IF(C3="","; Missing Ship Date","")&IF(P3<0,"; Invalid Discount (Negative)","")&IF(P3>0.5,"; Invalid Discount (Too High)","")&IF(Z3<0,"; Invalid Shipping Record (Ship Before Order)","")&IF(ABS(Q3-W3)>1,"; Sales Mismatch","")&IF(ABS(S3-X3)>1,"; Profit Mismatch","")&IF(COUNTIF($A$2:$A$913,A3)>1,"; Duplicate Order ID Conflict","")) | AE3: =IF(OR(ISNUMBER(SEARCH("Invalid Discount",AD3)),ISNUMBER(SEARCH("Invalid Shipping Record",AD3)),ISNUMBER(SEARCH("Sales Mismatch",AD3)),ISNUMBER(SEARCH("Profit Mismatch",AD3)),ISNUMBER(SEARCH("Duplicate Order ID Conflict",AD3)),ISNUMBER(SEARCH("Missing Order Date",AD3)),ISNUMBER(SEARCH("Missing Ship Date",AD3))),"Invalid",IF(AD3<>"","Warning","Clean")) -> Clean
A4: ORD-2024-10003 | B4: 45451 | C4: 45458 | D4: CUST-6843 | E4: =PROPER(TRIM(SUBSTITUTE(Raw_Text_Fields!B5,CHAR(160)," "))) -> Isha Nair | F4: =PROPER(TRIM(SUBSTITUTE(Raw_Text_Fields!C5,CHAR(160)," "))) -> Consumer | G4: =PROPER(TRIM(SUBSTITUTE(Raw_Text_Fields!D5,CHAR(160)," "))) -> East | H4: =PROPER(TRIM(SUBSTITUTE(Raw_Text_Fields!E5,CHAR(160)," "))) -> Odisha | I4: =PROPER(TRIM(SUBSTITUTE(Raw_Text_Fields!F5,CHAR(160)," "))) -> Bhubaneswar | J4: =PROPER(TRIM(SUBSTITUTE(Raw_Text_Fields!G5,CHAR(160)," "))) -> Office Supplies | K4: =PROPER(TRIM(SUBSTITUTE(Raw_Text_Fields!H5,CHAR(160)," "))) -> Art | L4: Elite Art 525 | M4: =PROPER(TRIM(SUBSTITUTE(Raw_Text_Fields!I5,CHAR(160)," "))) -> First Class | N4: 4 | O4: 1065.43 | P4: 0.55 | Q4: 4261.72 | R4: 2465.69 | S4: 1796.03 | T4: =PROPER(TRIM(SUBSTITUTE(Raw_Text_Fields!J5,CHAR(160)," "))) -> Paid | U4: =PROPER(TRIM(SUBSTITUTE(Raw_Text_Fields!K5,CHAR(160)," "))) -> Completed | V4: =IF(OR(P4<0,P4>0.5),0,P4) -> 0 | W4: =N4*O4*(1-V4) -> 4261.72 | X4: =W4-R4 -> 1796.03 | Y4: =IFERROR(X4/W4,0) -> 0.42143313 | Z4: =C4-B4 -> 7 | AA4: =IF(B4="","",TEXT(B4,"mmm")) -> Jun | AB4: =IF(B4="","",YEAR(B4)) -> 2024 | AD4: =IF(LEFT(AC4&IF(B4="","; Missing Order Date","")&IF(C4="","; Missing Ship Date","")&IF(P4<0,"; Invalid Discount (Negative)","")&IF(P4>0.5,"; Invalid Discount (Too High)","")&IF(Z4<0,"; Invalid Shipping Record (Ship Before Order)","")&IF(ABS(Q4-W4)>1,"; Sales Mismatch","")&IF(ABS(S4-X4)>1,"; Profit Mismatch","")&IF(COUNTIF($A$2:$A$913,A4)>1,"; Duplicate Order ID Conflict",""),2)="; ",MID(AC4&IF(B4="","; Missing Order Date","")&IF(C4="","; Missing Ship Date","")&IF(P4<0,"; Invalid Discount (Negative)","")&IF(P4>0.5,"; Invalid Discount (Too High)","")&IF(Z4<0,"; Invalid Shipping Record (Ship Before Order)","")&IF(ABS(Q4-W4)>1,"; Sales Mismatch","")&IF(ABS(S4-X4)>1,"; Profit Mismatch","")&IF(COUNTIF($A$2:$A$913,A4)>1,"; Duplicate Order ID Conflict",""),3,500),AC4&IF(B4="","; Missing Order Date","")&IF(C4="","; Missing Ship Date","")&IF(P4<0,"; Invalid Discount (Negative)","")&IF(P4>0.5,"; Invalid Discount (Too High)","")&IF(Z4<0,"; Invalid Shipping Record (Ship Before Order)","")&IF(ABS(Q4-W4)>1,"; Sales Mismatch","")&IF(ABS(S4-X4)>1,"; Profit Mismatch","")&IF(COUNTIF($A$2:$A$913,A4)>1,"; Duplicate Order ID Conflict","")) -> Invalid Discount (Too High) | AE4: =IF(OR(ISNUMBER(SEARCH("Invalid Discount",AD4)),ISNUMBER(SEARCH("Invalid Shipping Record",AD4)),ISNUMBER(SEARCH("Sales Mismatch",AD4)),ISNUMBER(SEARCH("Profit Mismatch",AD4)),ISNUMBER(SEARCH("Duplicate Order ID Conflict",AD4)),ISNUMBER(SEARCH("Missing Order Date",AD4)),ISNUMBER(SEARCH("Missing Ship Date",AD4))),"Invalid",IF(AD4<>"","Warning","Clean")) -> Invalid
A5: ORD-2024-10004 | B5: 45624 | C5: 45625 | D5: CUST-3722 | E5: =PROPER(TRIM(SUBSTITUTE(Raw_Text_Fields!B6,CHAR(160)," "))) -> Arjun Bose | F5: =PROPER(TRIM(SUBSTITUTE(Raw_Text_Fields!C6,CHAR(160)," "))) -> Small Business | G5: =PROPER(TRIM(SUBSTITUTE(Raw_Text_Fields!D6,CHAR(160)," "))) -> South | H5: =PROPER(TRIM(SUBSTITUTE(Raw_Text_Fields!E6,CHAR(160)," "))) -> Telangana | I5: =PROPER(TRIM(SUBSTITUTE(Raw_Text_Fields!F6,CHAR(160)," "))) -> Hyderabad | J5: =PROPER(TRIM(SUBSTITUTE(Raw_Text_Fields!G6,CHAR(160)," "))) -> Furniture | K5: =PROPER(TRIM(SUBSTITUTE(Raw_Text_Fields!H6,CHAR(160)," "))) -> Furnishings | L5: Smart Furnishings 294 | M5: =PROPER(TRIM(SUBSTITUTE(Raw_Text_Fields!I6,CHAR(160)," "))) -> Standard Class | N5: 6 | O5: 1848.43 | P5: 0.25 | Q5: 8317.93 | R5: 6796.77 | S5: 1521.16 | T5: =PROPER(TRIM(SUBSTITUTE(Raw_Text_Fields!J6,CHAR(160)," "))) -> Paid | U5: =PROPER(TRIM(SUBSTITUTE(Raw_Text_Fields!K6,CHAR(160)," "))) -> Completed | V5: =IF(OR(P5<0,P5>0.5),0,P5) -> 0.25 | W5: =N5*O5*(1-V5) -> 8317.935 | X5: =W5-R5 -> 1521.165 | Y5: =IFERROR(X5/W5,0) -> 0.18287772 | Z5: =C5-B5 -> 1 | AA5: =IF(B5="","",TEXT(B5,"mmm")) -> Nov | AB5: =IF(B5="","",YEAR(B5)) -> 2024 | AD5: =IF(LEFT(AC5&IF(B5="","; Missing Order Date","")&IF(C5="","; Missing Ship Date","")&IF(P5<0,"; Invalid Discount (Negative)","")&IF(P5>0.5,"; Invalid Discount (Too High)","")&IF(Z5<0,"; Invalid Shipping Record (Ship Before Order)","")&IF(ABS(Q5-W5)>1,"; Sales Mismatch","")&IF(ABS(S5-X5)>1,"; Profit Mismatch","")&IF(COUNTIF($A$2:$A$913,A5)>1,"; Duplicate Order ID Conflict",""),2)="; ",MID(AC5&IF(B5="","; Missing Order Date","")&IF(C5="","; Missing Ship Date","")&IF(P5<0,"; Invalid Discount (Negative)","")&IF(P5>0.5,"; Invalid Discount (Too High)","")&IF(Z5<0,"; Invalid Shipping Record (Ship Before Order)","")&IF(ABS(Q5-W5)>1,"; Sales Mismatch","")&IF(ABS(S5-X5)>1,"; Profit Mismatch","")&IF(COUNTIF($A$2:$A$913,A5)>1,"; Duplicate Order ID Conflict",""),3,500),AC5&IF(B5="","; Missing Order Date","")&IF(C5="","; Missing Ship Date","")&IF(P5<0,"; Invalid Discount (Negative)","")&IF(P5>0.5,"; Invalid Discount (Too High)","")&IF(Z5<0,"; Invalid Shipping Record (Ship Before Order)","")&IF(ABS(Q5-W5)>1,"; Sales Mismatch","")&IF(ABS(S5-X5)>1,"; Profit Mismatch","")&IF(COUNTIF($A$2:$A$913,A5)>1,"; Duplicate Order ID Conflict","")) | AE5: =IF(OR(ISNUMBER(SEARCH("Invalid Discount",AD5)),ISNUMBER(SEARCH("Invalid Shipping Record",AD5)),ISNUMBER(SEARCH("Sales Mismatch",AD5)),ISNUMBER(SEARCH("Profit Mismatch",AD5)),ISNUMBER(SEARCH("Duplicate Order ID Conflict",AD5)),ISNUMBER(SEARCH("Missing Order Date",AD5)),ISNUMBER(SEARCH("Missing Ship Date",AD5))),"Invalid",IF(AD5<>"","Warning","Clean")) -> Clean
A6: ORD-2025-10005 | B6: 45898 | C6: 45901 | D6: CUST-8130 | E6: =PROPER(TRIM(SUBSTITUTE(Raw_Text_Fields!B7,CHAR(160)," "))) -> Ananya Rao | F6: =PROPER(TRIM(SUBSTITUTE(Raw_Text_Fields!C7,CHAR(160)," "))) -> Small Business | G6: =PROPER(TRIM(SUBSTITUTE(Raw_Text_Fields!D7,CHAR(160)," "))) -> West | H6: =PROPER(TRIM(SUBSTITUTE(Raw_Text_Fields!E7,CHAR(160)," "))) -> Maharashtra | I6: =PROPER(TRIM(SUBSTITUTE(Raw_Text_Fields!F7,CHAR(160)," "))) -> Mumbai | J6: =PROPER(TRIM(SUBSTITUTE(Raw_Text_Fields!G7,CHAR(160)," "))) -> Furniture | K6: =PROPER(TRIM(SUBSTITUTE(Raw_Text_Fields!H7,CHAR(160)," "))) -> Chairs | L6: Elite Chairs 543 | M6: =PROPER(TRIM(SUBSTITUTE(Raw_Text_Fields!I7,CHAR(160)," "))) -> First Class | N6: 7 | O6: 2973.76 | P6: 0 | Q6: 20816.32 | R6: 17705.37 | S6: 3110.95 | T6: =PROPER(TRIM(SUBSTITUTE(Raw_Text_Fields!J7,CHAR(160)," "))) -> Paid | U6: =PROPER(TRIM(SUBSTITUTE(Raw_Text_Fields!K7,CHAR(160)," "))) -> Cancelled | V6: =IF(OR(P6<0,P6>0.5),0,P6) -> 0 | W6: =N6*O6*(1-V6) -> 20816.32 | X6: =W6-R6 -> 3110.95 | Y6: =IFERROR(X6/W6,0) -> 0.14944764 | Z6: =C6-B6 -> 3 | AA6: =IF(B6="","",TEXT(B6,"mmm")) -> Aug | AB6: =IF(B6="","",YEAR(B6)) -> 2025 | AD6: =IF(LEFT(AC6&IF(B6="","; Missing Order Date","")&IF(C6="","; Missing Ship Date","")&IF(P6<0,"; Invalid Discount (Negative)","")&IF(P6>0.5,"; Invalid Discount (Too High)","")&IF(Z6<0,"; Invalid Shipping Record (Ship Before Order)","")&IF(ABS(Q6-W6)>1,"; Sales Mismatch","")&IF(ABS(S6-X6)>1,"; Profit Mismatch","")&IF(COUNTIF($A$2:$A$913,A6)>1,"; Duplicate Order ID Conflict",""),2)="; ",MID(AC6&IF(B6="","; Missing Order Date","")&IF(C6="","; Missing Ship Date","")&IF(P6<0,"; Invalid Discount (Negative)","")&IF(P6>0.5,"; Invalid Discount (Too High)","")&IF(Z6<0,"; Invalid Shipping Record (Ship Before Order)","")&IF(ABS(Q6-W6)>1,"; Sales Mismatch","")&IF(ABS(S6-X6)>1,"; Profit Mismatch","")&IF(COUNTIF($A$2:$A$913,A6)>1,"; Duplicate Order ID Conflict",""),3,500),AC6&IF(B6="","; Missing Order Date","")&IF(C6="","; Missing Ship Date","")&IF(P6<0,"; Invalid Discount (Negative)","")&IF(P6>0.5,"; Invalid Discount (Too High)","")&IF(Z6<0,"; Invalid Shipping Record (Ship Before Order)","")&IF(ABS(Q6-W6)>1,"; Sales Mismatch","")&IF(ABS(S6-X6)>1,"; Profit Mismatch","")&IF(COUNTIF($A$2:$A$913,A6)>1,"; Duplicate Order ID Conflict","")) | AE6: =IF(OR(ISNUMBER(SEARCH("Invalid Discount",AD6)),ISNUMBER(SEARCH("Invalid Shipping Record",AD6)),ISNUMBER(SEARCH("Sales Mismatch",AD6)),ISNUMBER(SEARCH("Profit Mismatch",AD6)),ISNUMBER(SEARCH("Duplicate Order ID Conflict",AD6)),ISNUMBER(SEARCH("Missing Order Date",AD6)),ISNUMBER(SEARCH("Missing Ship Date",AD6))),"Invalid",IF(AD6<>"","Warning","Clean")) -> Clean
A7: ORD-2024-10006 | B7: 45436 | C7: 45440 | D7: CUST-6056 | E7: =PROPER(TRIM(SUBSTITUTE(Raw_Text_Fields!B8,CHAR(160)," "))) -> Vikram Iyer | F7: =PROPER(TRIM(SUBSTITUTE(Raw_Text_Fields!C8,CHAR(160)," "))) -> Small Business | G7: =PROPER(TRIM(SUBSTITUTE(Raw_Text_Fields!D8,CHAR(160)," "))) -> West | H7: =PROPER(TRIM(SUBSTITUTE(Raw_Text_Fields!E8,CHAR(160)," "))) -> Madhya Pradesh | I7: =PROPER(TRIM(SUBSTITUTE(Raw_Text_Fields!F8,CHAR(160)," "))) -> Indore | J7: =PROPER(TRIM(SUBSTITUTE(Raw_Text_Fields!G8,CHAR(160)," "))) -> Technology | K7: =PROPER(TRIM(SUBSTITUTE(Raw_Text_Fields!H8,CHAR(160)," "))) -> Accessories | L7: Pro Accessories 821 | M7: =PROPER(TRIM(SUBSTITUTE(Raw_Text_Fields!I8,CHAR(160)," "))) -> Same Day | N7: 3 | O7: 1053.11 | P7: 0.2 | Q7: 2527.46 | R7: 1533.58 | S7: 993.88 | T7: =PROPER(TRIM(SUBSTITUTE(Raw_Text_Fields!J8,CHAR(160)," "))) -> Paid | U7: =PROPER(TRIM(SUBSTITUTE(Raw_Text_Fields!K8,CHAR(160)," "))) -> Completed | V7: =IF(OR(P7<0,P7>0.5),0,P7) -> 0.2 | W7: =N7*O7*(1-V7) -> 2527.464 | X7: =W7-R7 -> 993.884 | Y7: =IFERROR(X7/W7,0) -> 0.39323369 | Z7: =C7-B7 -> 4 | AA7: =IF(B7="","",TEXT(B7,"mmm")) -> May | AB7: =IF(B7="","",YEAR(B7)) -> 2024 | AD7: =IF(LEFT(AC7&IF(B7="","; Missing Order Date","")&IF(C7="","; Missing Ship Date","")&IF(P7<0,"; Invalid Discount (Negative)","")&IF(P7>0.5,"; Invalid Discount (Too High)","")&IF(Z7<0,"; Invalid Shipping Record (Ship Before Order)","")&IF(ABS(Q7-W7)>1,"; Sales Mismatch","")&IF(ABS(S7-X7)>1,"; Profit Mismatch","")&IF(COUNTIF($A$2:$A$913,A7)>1,"; Duplicate Order ID Conflict",""),2)="; ",MID(AC7&IF(B7="","; Missing Order Date","")&IF(C7="","; Missing Ship Date","")&IF(P7<0,"; Invalid Discount (Negative)","")&IF(P7>0.5,"; Invalid Discount (Too High)","")&IF(Z7<0,"; Invalid Shipping Record (Ship Before Order)","")&IF(ABS(Q7-W7)>1,"; Sales Mismatch","")&IF(ABS(S7-X7)>1,"; Profit Mismatch","")&IF(COUNTIF($A$2:$A$913,A7)>1,"; Duplicate Order ID Conflict",""),3,500),AC7&IF(B7="","; Missing Order Date","")&IF(C7="","; Missing Ship Date","")&IF(P7<0,"; Invalid Discount (Negative)","")&IF(P7>0.5,"; Invalid Discount (Too High)","")&IF(Z7<0,"; Invalid Shipping Record (Ship Before Order)","")&IF(ABS(Q7-W7)>1,"; Sales Mismatch","")&IF(ABS(S7-X7)>1,"; Profit Mismatch","")&IF(COUNTIF($A$2:$A$913,A7)>1,"; Duplicate Order ID Conflict","")) | AE7: =IF(OR(ISNUMBER(SEARCH("Invalid Discount",AD7)),ISNUMBER(SEARCH("Invalid Shipping Record",AD7)),ISNUMBER(SEARCH("Sales Mismatch",AD7)),ISNUMBER(SEARCH("Profit Mismatch",AD7)),ISNUMBER(SEARCH("Duplicate Order ID Conflict",AD7)),ISNUMBER(SEARCH("Missing Order Date",AD7)),ISNUMBER(SEARCH("Missing Ship Date",AD7))),"Invalid",IF(AD7<>"","Warning","Clean")) -> Clean
A8: ORD-2025-10007 | B8: 45757 | C8: 45763 | D8: CUST-3656 | E8: =PROPER(TRIM(SUBSTITUTE(Raw_Text_Fields!B9,CHAR(160)," "))) -> Neha Gupta | F8: =PROPER(TRIM(SUBSTITUTE(Raw_Text_Fields!C9,CHAR(160)," "))) -> Consumer | G8: =PROPER(TRIM(SUBSTITUTE(Raw_Text_Fields!D9,CHAR(160)," "))) -> East | H8: =PROPER(TRIM(SUBSTITUTE(Raw_Text_Fields!E9,CHAR(160)," "))) -> Odisha | I8: =PROPER(TRIM(SUBSTITUTE(Raw_Text_Fields!F9,CHAR(160)," "))) -> Bhubaneswar | J8: =PROPER(TRIM(SUBSTITUTE(Raw_Text_Fields!G9,CHAR(160)," "))) -> Technology | K8: =PROPER(TRIM(SUBSTITUTE(Raw_Text_Fields!H9,CHAR(160)," "))) -> Copiers | L8: Eco Copiers 790 | M8: =PROPER(TRIM(SUBSTITUTE(Raw_Text_Fields!I9,CHAR(160)," "))) -> Standard Class | N8: 4 | O8: 1719.87 | P8: 0.15 | Q8: 5847.56 | R8: 4727.25 | S8: 1120.31 | T8: =PROPER(TRIM(SUBSTITUTE(Raw_Text_Fields!J9,CHAR(160)," "))) -> Paid | U8: =PROPER(TRIM(SUBSTITUTE(Raw_Text_Fields!K9,CHAR(160)," "))) -> Completed | V8: =IF(OR(P8<0,P8>0.5),0,P8) -> 0.15 | W8: =N8*O8*(1-V8) -> 5847.558 | X8: =W8-R8 -> 1120.308 | Y8: =IFERROR(X8/W8,0) -> 0.19158562 | Z8: =C8-B8 -> 6 | AA8: =IF(B8="","",TEXT(B8,"mmm")) -> Apr | AB8: =IF(B8="","",YEAR(B8)) -> 2025 | AD8: =IF(LEFT(AC8&IF(B8="","; Missing Order Date","")&IF(C8="","; Missing Ship Date","")&IF(P8<0,"; Invalid Discount (Negative)","")&IF(P8>0.5,"; Invalid Discount (Too High)","")&IF(Z8<0,"; Invalid Shipping Record (Ship Before Order)","")&IF(ABS(Q8-W8)>1,"; Sales Mismatch","")&IF(ABS(S8-X8)>1,"; Profit Mismatch","")&IF(COUNTIF($A$2:$A$913,A8)>1,"; Duplicate Order ID Conflict",""),2)="; ",MID(AC8&IF(B8="","; Missing Order Date","")&IF(C8="","; Missing Ship Date","")&IF(P8<0,"; Invalid Discount (Negative)","")&IF(P8>0.5,"; Invalid Discount (Too High)","")&IF(Z8<0,"; Invalid Shipping Record (Ship Before Order)","")&IF(ABS(Q8-W8)>1,"; Sales Mismatch","")&IF(ABS(S8-X8)>1,"; Profit Mismatch","")&IF(COUNTIF($A$2:$A$913,A8)>1,"; Duplicate Order ID Conflict",""),3,500),AC8&IF(B8="","; Missing Order Date","")&IF(C8="","; Missing Ship Date","")&IF(P8<0,"; Invalid Discount (Negative)","")&IF(P8>0.5,"; Invalid Discount (Too High)","")&IF(Z8<0,"; Invalid Shipping Record (Ship Before Order)","")&IF(ABS(Q8-W8)>1,"; Sales Mismatch","")&IF(ABS(S8-X8)>1,"; Profit Mismatch","")&IF(COUNTIF($A$2:$A$913,A8)>1,"; Duplicate Order ID Conflict","")) | AE8: =IF(OR(ISNUMBER(SEARCH("Invalid Discount",AD8)),ISNUMBER(SEARCH("Invalid Shipping Record",AD8)),ISNUMBER(SEARCH("Sales Mismatch",AD8)),ISNUMBER(SEARCH("Profit Mismatch",AD8)),ISNUMBER(SEARCH("Duplicate Order ID Conflict",AD8)),ISNUMBER(SEARCH("Missing Order Date",AD8)),ISNUMBER(SEARCH("Missing Ship Date",AD8))),"Invalid",IF(AD8<>"","Warning","Clean")) -> Clean
A9: ORD-2025-10008 | B9: 45711 | C9: 45714 | D9: CUST-4683 | E9: =PROPER(TRIM(SUBSTITUTE(Raw_Text_Fields!B10,CHAR(160)," "))) -> Isha Nair | F9: =PROPER(TRIM(SUBSTITUTE(Raw_Text_Fields!C10,CHAR(160)," "))) -> Small Business | G9: =PROPER(TRIM(SUBSTITUTE(Raw_Text_Fields!D10,CHAR(160)," "))) -> South | H9: =PROPER(TRIM(SUBSTITUTE(Raw_Text_Fields!E10,CHAR(160)," "))) -> Andhra Pradesh | I9: =PROPER(TRIM(SUBSTITUTE(Raw_Text_Fields!F10,CHAR(160)," "))) -> Vijayawada | J9: =PROPER(TRIM(SUBSTITUTE(Raw_Text_Fields!G10,CHAR(160)," "))) -> Office Supplies | K9: =PROPER(TRIM(SUBSTITUTE(Raw_Text_Fields!H10,CHAR(160)," "))) -> Art | L9: Eco Art 848 | M9: =PROPER(TRIM(SUBSTITUTE(Raw_Text_Fields!I10,CHAR(160)," "))) -> First Class | N9: 1 | O9: 2980.71 | P9: 0 | Q9: 2980.71 | R9: 2357.22 | S9: 623.49 | T9: =PROPER(TRIM(SUBSTITUTE(Raw_Text_Fields!J10,CHAR(160)," "))) -> Paid | U9: =PROPER(TRIM(SUBSTITUTE(Raw_Text_Fields!K10,CHAR(160)," "))) -> Completed | V9: =IF(OR(P9<0,P9>0.5),0,P9) -> 0 | W9: =N9*O9*(1-V9) -> 2980.71 | X9: =W9-R9 -> 623.49 | Y9: =IFERROR(X9/W9,0) -> 0.209175 | Z9: =C9-B9 -> 3 | AA9: =IF(B9="","",TEXT(B9,"mmm")) -> Feb | AB9: =IF(B9="","",YEAR(B9)) -> 2025 | AD9: =IF(LEFT(AC9&IF(B9="","; Missing Order Date","")&IF(C9="","; Missing Ship Date","")&IF(P9<0,"; Invalid Discount (Negative)","")&IF(P9>0.5,"; Invalid Discount (Too High)","")&IF(Z9<0,"; Invalid Shipping Record (Ship Before Order)","")&IF(ABS(Q9-W9)>1,"; Sales Mismatch","")&IF(ABS(S9-X9)>1,"; Profit Mismatch","")&IF(COUNTIF($A$2:$A$913,A9)>1,"; Duplicate Order ID Conflict",""),2)="; ",MID(AC9&IF(B9="","; Missing Order Date","")&IF(C9="","; Missing Ship Date","")&IF(P9<0,"; Invalid Discount (Negative)","")&IF(P9>0.5,"; Invalid Discount (Too High)","")&IF(Z9<0,"; Invalid Shipping Record (Ship Before Order)","")&IF(ABS(Q9-W9)>1,"; Sales Mismatch","")&IF(ABS(S9-X9)>1,"; Profit Mismatch","")&IF(COUNTIF($A$2:$A$913,A9)>1,"; Duplicate Order ID Conflict",""),3,500),AC9&IF(B9="","; Missing Order Date","")&IF(C9="","; Missing Ship Date","")&IF(P9<0,"; Invalid Discount (Negative)","")&IF(P9>0.5,"; Invalid Discount (Too High)","")&IF(Z9<0,"; Invalid Shipping Record (Ship Before Order)","")&IF(ABS(Q9-W9)>1,"; Sales Mismatch","")&IF(ABS(S9-X9)>1,"; Profit Mismatch","")&IF(COUNTIF($A$2:$A$913,A9)>1,"; Duplicate Order ID Conflict","")) | AE9: =IF(OR(ISNUMBER(SEARCH("Invalid Discount",AD9)),ISNUMBER(SEARCH("Invalid Shipping Record",AD9)),ISNUMBER(SEARCH("Sales Mismatch",AD9)),ISNUMBER(SEARCH("Profit Mismatch",AD9)),ISNUMBER(SEARCH("Duplicate Order ID Conflict",AD9)),ISNUMBER(SEARCH("Missing Order Date",AD9)),ISNUMBER(SEARCH("Missing Ship Date",AD9))),"Invalid",IF(AD9<>"","Warning","Clean")) -> Clean
A10: ORD-2024-10009 | B10: 45601 | C10: 45606 | D10: CUST-2598 | E10: =PROPER(TRIM(SUBSTITUTE(Raw_Text_Fields!B11,CHAR(160)," "))) -> Aditi Sen | F10: =PROPER(TRIM(SUBSTITUTE(Raw_Text_Fields!C11,CHAR(160)," "))) -> Corporate | G10: =PROPER(TRIM(SUBSTITUTE(Raw_Text_Fields!D11,CHAR(160)," "))) -> South | H10: =PROPER(TRIM(SUBSTITUTE(Raw_Text_Fields!E11,CHAR(160)," "))) -> Telangana | I10: =PROPER(TRIM(SUBSTITUTE(Raw_Text_Fields!F11,CHAR(160)," "))) -> Hyderabad | J10: =PROPER(TRIM(SUBSTITUTE(Raw_Text_Fields!G11,CHAR(160)," "))) -> Office Supplies | K10: =PROPER(TRIM(SUBSTITUTE(Raw_Text_Fields!H11,CHAR(160)," "))) -> Labels | L10: Classic Labels 815 | M10: =PROPER(TRIM(SUBSTITUTE(Raw_Text_Fields!I11,CHAR(160)," "))) -> First Class | N10: 8 | O10: 3134.2 | P10: 0 | Q10: 25073.6 | R10: 17347.23 | S10: 7726.37 | T10: =PROPER(TRIM(SUBSTITUTE(Raw_Text_Fields!J11,CHAR(160)," "))) -> Paid | U10: =PROPER(TRIM(SUBSTITUTE(Raw_Text_Fields!K11,CHAR(160)," "))) -> Completed | V10: =IF(OR(P10<0,P10>0.5),0,P10) -> 0 | W10: =N10*O10*(1-V10) -> 25073.6 | X10: =W10-R10 -> 7726.37 | Y10: =IFERROR(X10/W10,0) -> 0.30814761 | Z10: =C10-B10 -> 5 | AA10: =IF(B10="","",TEXT(B10,"mmm")) -> Nov | AB10: =IF(B10="","",YEAR(B10)) -> 2024 | AD10: =IF(LEFT(AC10&IF(B10="","; Missing Order Date","")&IF(C10="","; Missing Ship Date","")&IF(P10<0,"; Invalid Discount (Negative)","")&IF(P10>0.5,"; Invalid Discount (Too High)","")&IF(Z10<0,"; Invalid Shipping Record (Ship Before Order)","")&IF(ABS(Q10-W10)>1,"; Sales Mismatch","")&IF(ABS(S10-X10)>1,"; Profit Mismatch","")&IF(COUNTIF($A$2:$A$913,A10)>1,"; Duplicate Order ID Conflict",""),2)="; ",MID(AC10&IF(B10="","; Missing Order Date","")&IF(C10="","; Missing Ship Date","")&IF(P10<0,"; Invalid Discount (Negative)","")&IF(P10>0.5,"; Invalid Discount (Too High)","")&IF(Z10<0,"; Invalid Shipping Record (Ship Before Order)","")&IF(ABS(Q10-W10)>1,"; Sales Mismatch","")&IF(ABS(S10-X10)>1,"; Profit Mismatch","")&IF(COUNTIF($A$2:$A$913,A10)>1,"; Duplicate Order ID Conflict",""),3,500),AC10&IF(B10="","; Missing Order Date","")&IF(C10="","; Missing Ship Date","")&IF(P10<0,"; Invalid Discount (Negative)","")&IF(P10>0.5,"; Invalid Discount (Too High)","")&IF(Z10<0,"; Invalid Shipping Record (Ship Before Order)","")&IF(ABS(Q10-W10)>1,"; Sales Mismatch","")&IF(ABS(S10-X10)>1,"; Profit Mismatch","")&IF(COUNTIF($A$2:$A$913,A10)>1,"; Duplicate Order ID Conflict","")) | AE10: =IF(OR(ISNUMBER(SEARCH("Invalid Discount",AD10)),ISNUMBER(SEARCH("Invalid Shipping Record",AD10)),ISNUMBER(SEARCH("Sales Mismatch",AD10)),ISNUMBER(SEARCH("Profit Mismatch",AD10)),ISNUMBER(SEARCH("Duplicate Order ID Conflict",AD10)),ISNUMBER(SEARCH("Missing Order Date",AD10)),ISNUMBER(SEARCH("Missing Ship Date",AD10))),"Invalid",IF(AD10<>"","Warning","Clean")) -> Clean
A11: ORD-2025-10010 | B11: 45907 | C11: 45912 | D11: CUST-2483 | E11: =PROPER(TRIM(SUBSTITUTE(Raw_Text_Fields!B12,CHAR(160)," "))) -> Mira Das | F11: =PROPER(TRIM(SUBSTITUTE(Raw_Text_Fields!C12,CHAR(160)," "))) -> Home Office | G11: =PROPER(TRIM(SUBSTITUTE(Raw_Text_Fields!D12,CHAR(160)," "))) -> South | H11: =PROPER(TRIM(SUBSTITUTE(Raw_Text_Fields!E12,CHAR(160)," "))) -> Telangana | I11: =PROPER(TRIM(SUBSTITUTE(Raw_Text_Fields!F12,CHAR(160)," "))) -> Hyderabad | J11: =PROPER(TRIM(SUBSTITUTE(Raw_Text_Fields!G12,CHAR(160)," "))) -> Office Supplies | K11: =PROPER(TRIM(SUBSTITUTE(Raw_Text_Fields!H12,CHAR(160)," "))) -> Paper | L11: Pro Paper 622 | M11: =PROPER(TRIM(SUBSTITUTE(Raw_Text_Fields!I12,CHAR(160)," "))) -> Second Class | N11: 9 | O11: 852.04 | P11: 0.2 | Q11: 6134.69 | R11: 3800.19 | S11: 2334.5 | T11: =PROPER(TRIM(SUBSTITUTE(Raw_Text_Fields!J12,CHAR(160)," "))) -> Paid | U11: =PROPER(TRIM(SUBSTITUTE(Raw_Text_Fields!K12,CHAR(160)," "))) -> Completed | V11: =IF(OR(P11<0,P11>0.5),0,P11) -> 0.2 | W11: =N11*O11*(1-V11) -> 6134.688 | X11: =W11-R11 -> 2334.498 | Y11: =IFERROR(X11/W11,0) -> 0.38054062 | Z11: =C11-B11 -> 5 | AA11: =IF(B11="","",TEXT(B11,"mmm")) -> Sep | AB11: =IF(B11="","",YEAR(B11)) -> 2025 | AD11: =IF(LEFT(AC11&IF(B11="","; Missing Order Date","")&IF(C11="","; Missing Ship Date","")&IF(P11<0,"; Invalid Discount (Negative)","")&IF(P11>0.5,"; Invalid Discount (Too High)","")&IF(Z11<0,"; Invalid Shipping Record (Ship Before Order)","")&IF(ABS(Q11-W11)>1,"; Sales Mismatch","")&IF(ABS(S11-X11)>1,"; Profit Mismatch","")&IF(COUNTIF($A$2:$A$913,A11)>1,"; Duplicate Order ID Conflict",""),2)="; ",MID(AC11&IF(B11="","; Missing Order Date","")&IF(C11="","; Missing Ship Date","")&IF(P11<0,"; Invalid Discount (Negative)","")&IF(P11>0.5,"; Invalid Discount (Too High)","")&IF(Z11<0,"; Invalid Shipping Record (Ship Before Order)","")&IF(ABS(Q11-W11)>1,"; Sales Mismatch","")&IF(ABS(S11-X11)>1,"; Profit Mismatch","")&IF(COUNTIF($A$2:$A$913,A11)>1,"; Duplicate Order ID Conflict",""),3,500),AC11&IF(B11="","; Missing Order Date","")&IF(C11="","; Missing Ship Date","")&IF(P11<0,"; Invalid Discount (Negative)","")&IF(P11>0.5,"; Invalid Discount (Too High)","")&IF(Z11<0,"; Invalid Shipping Record (Ship Before Order)","")&IF(ABS(Q11-W11)>1,"; Sales Mismatch","")&IF(ABS(S11-X11)>1,"; Profit Mismatch","")&IF(COUNTIF($A$2:$A$913,A11)>1,"; Duplicate Order ID Conflict","")) | AE11: =IF(OR(ISNUMBER(SEARCH("Invalid Discount",AD11)),ISNUMBER(SEARCH("Invalid Shipping Record",AD11)),ISNUMBER(SEARCH("Sales Mismatch",AD11)),ISNUMBER(SEARCH("Profit Mismatch",AD11)),ISNUMBER(SEARCH("Duplicate Order ID Conflict",AD11)),ISNUMBER(SEARCH("Missing Order Date",AD11)),ISNUMBER(SEARCH("Missing Ship Date",AD11))),"Invalid",IF(AD11<>"","Warning","Clean")) -> Clean
A12: ORD-2025-10011 | B12: 45797 | C12: 45797 | D12: CUST-8092 | E12: =PROPER(TRIM(SUBSTITUTE(Raw_Text_Fields!B13,CHAR(160)," "))) -> Ananya Rao | F12: =PROPER(TRIM(SUBSTITUTE(Raw_Text_Fields!C13,CHAR(160)," "))) -> Corporate | G12: =PROPER(TRIM(SUBSTITUTE(Raw_Text_Fields!D13,CHAR(160)," "))) -> East | H12: =PROPER(TRIM(SUBSTITUTE(Raw_Text_Fields!E13,CHAR(160)," "))) -> West Bengal | I12: =PROPER(TRIM(SUBSTITUTE(Raw_Text_Fields!F13,CHAR(160)," "))) -> Kolkata | J12: =PROPER(TRIM(SUBSTITUTE(Raw_Text_Fields!G13,CHAR(160)," "))) -> Office Supplies | K12: =PROPER(TRIM(SUBSTITUTE(Raw_Text_Fields!H13,CHAR(160)," "))) -> Labels | L12: Prime Labels 644 | M12: =PROPER(TRIM(SUBSTITUTE(Raw_Text_Fields!I13,CHAR(160)," "))) -> Second Class | N12: 3 | O12: 3534.83 | P12: 0.05 | Q12: 10074.27 | R12: 6048.27 | S12: 4026 | T12: =PROPER(TRIM(SUBSTITUTE(Raw_Text_Fields!J13,CHAR(160)," "))) -> Refunded | U12: =PROPER(TRIM(SUBSTITUTE(Raw_Text_Fields!K13,CHAR(160)," "))) -> Returned | V12: =IF(OR(P12<0,P12>0.5),0,P12) -> 0.05 | W12: =N12*O12*(1-V12) -> 10074.265 | X12: =W12-R12 -> 4025.9955 | Y12: =IFERROR(X12/W12,0) -> 0.39963167 | Z12: =C12-B12 -> 0 | AA12: =IF(B12="","",TEXT(B12,"mmm")) -> May | AB12: =IF(B12="","",YEAR(B12)) -> 2025 | AD12: =IF(LEFT(AC12&IF(B12="","; Missing Order Date","")&IF(C12="","; Missing Ship Date","")&IF(P12<0,"; Invalid Discount (Negative)","")&IF(P12>0.5,"; Invalid Discount (Too High)","")&IF(Z12<0,"; Invalid Shipping Record (Ship Before Order)","")&IF(ABS(Q12-W12)>1,"; Sales Mismatch","")&IF(ABS(S12-X12)>1,"; Profit Mismatch","")&IF(COUNTIF($A$2:$A$913,A12)>1,"; Duplicate Order ID Conflict",""),2)="; ",MID(AC12&IF(B12="","; Missing Order Date","")&IF(C12="","; Missing Ship Date","")&IF(P12<0,"; Invalid Discount (Negative)","")&IF(P12>0.5,"; Invalid Discount (Too High)","")&IF(Z12<0,"; Invalid Shipping Record (Ship Before Order)","")&IF(ABS(Q12-W12)>1,"; Sales Mismatch","")&IF(ABS(S12-X12)>1,"; Profit Mismatch","")&IF(COUNTIF($A$2:$A$913,A12)>1,"; Duplicate Order ID Conflict",""),3,500),AC12&IF(B12="","; Missing Order Date","")&IF(C12="","; Missing Ship Date","")&IF(P12<0,"; Invalid Discount (Negative)","")&IF(P12>0.5,"; Invalid Discount (Too High)","")&IF(Z12<0,"; Invalid Shipping Record (Ship Before Order)","")&IF(ABS(Q12-W12)>1,"; Sales Mismatch","")&IF(ABS(S12-X12)>1,"; Profit Mismatch","")&IF(COUNTIF($A$2:$A$913,A12)>1,"; Duplicate Order ID Conflict","")) | AE12: =IF(OR(ISNUMBER(SEARCH("Invalid Discount",AD12)),ISNUMBER(SEARCH("Invalid Shipping Record",AD12)),ISNUMBER(SEARCH("Sales Mismatch",AD12)),ISNUMBER(SEARCH("Profit Mismatch",AD12)),ISNUMBER(SEARCH("Duplicate Order ID Conflict",AD12)),ISNUMBER(SEARCH("Missing Order Date",AD12)),ISNUMBER(SEARCH("Missing Ship Date",AD12))),"Invalid",IF(AD12<>"","Warning","Clean")) -> Clean
A13: ORD-2024-10012 | B13: 45495 | C13: 45496 | D13: CUST-6528 | E13: =PROPER(TRIM(SUBSTITUTE(Raw_Text_Fields!B14,CHAR(160)," "))) -> Vikram Iyer | F13: =PROPER(TRIM(SUBSTITUTE(Raw_Text_Fields!C14,CHAR(160)," "))) -> Small Business | G13: =PROPER(TRIM(SUBSTITUTE(Raw_Text_Fields!D14,CHAR(160)," "))) -> East | H13: =PROPER(TRIM(SUBSTITUTE(Raw_Text_Fields!E14,CHAR(160)," "))) -> Odisha | I13: =PROPER(TRIM(SUBSTITUTE(Raw_Text_Fields!F14,CHAR(160)," "))) -> Bhubaneswar | J13: =PROPER(TRIM(SUBSTITUTE(Raw_Text_Fields!G14,CHAR(160)," "))) -> Technology | K13: =PROPER(TRIM(SUBSTITUTE(Raw_Text_Fields!H14,CHAR(160)," "))) -> Accessories | L13: Smart Accessories 603 | M13: =PROPER(TRIM(SUBSTITUTE(Raw_Text_Fields!I14,CHAR(160)," "))) -> Same Day | N13: 6 | O13: 2005.95 | P13: 0.2 | Q13: 9628.56 | R13: 8038.59 | S13: 1589.97 | T13: =PROPER(TRIM(SUBSTITUTE(Raw_Text_Fields!J14,CHAR(160)," "))) -> Paid | U13: =PROPER(TRIM(SUBSTITUTE(Raw_Text_Fields!K14,CHAR(160)," "))) -> Completed | V13: =IF(OR(P13<0,P13>0.5),0,P13) -> 0.2 | W13: =N13*O13*(1-V13) -> 9628.56 | X13: =W13-R13 -> 1589.97 | Y13: =IFERROR(X13/W13,0) -> 0.16513061 | Z13: =C13-B13 -> 1 | AA13: =IF(B13="","",TEXT(B13,"mmm")) -> Jul | AB13: =IF(B13="","",YEAR(B13)) -> 2024 | AD13: =IF(LEFT(AC13&IF(B13="","; Missing Order Date","")&IF(C13="","; Missing Ship Date","")&IF(P13<0,"; Invalid Discount (Negative)","")&IF(P13>0.5,"; Invalid Discount (Too High)","")&IF(Z13<0,"; Invalid Shipping Record (Ship Before Order)","")&IF(ABS(Q13-W13)>1,"; Sales Mismatch","")&IF(ABS(S13-X13)>1,"; Profit Mismatch","")&IF(COUNTIF($A$2:$A$913,A13)>1,"; Duplicate Order ID Conflict",""),2)="; ",MID(AC13&IF(B13="","; Missing Order Date","")&IF(C13="","; Missing Ship Date","")&IF(P13<0,"; Invalid Discount (Negative)","")&IF(P13>0.5,"; Invalid Discount (Too High)","")&IF(Z13<0,"; Invalid Shipping Record (Ship Before Order)","")&IF(ABS(Q13-W13)>1,"; Sales Mismatch","")&IF(ABS(S13-X13)>1,"; Profit Mismatch","")&IF(COUNTIF($A$2:$A$913,A13)>1,"; Duplicate Order ID Conflict",""),3,500),AC13&IF(B13="","; Missing Order Date","")&IF(C13="","; Missing Ship Date","")&IF(P13<0,"; Invalid Discount (Negative)","")&IF(P13>0.5,"; Invalid Discount (Too High)","")&IF(Z13<0,"; Invalid Shipping Record (Ship Before Order)","")&IF(ABS(Q13-W13)>1,"; Sales Mismatch","")&IF(ABS(S13-X13)>1,"; Profit Mismatch","")&IF(COUNTIF($A$2:$A$913,A13)>1,"; Duplicate Order ID Conflict","")) | AE13: =IF(OR(ISNUMBER(SEARCH("Invalid Discount",AD13)),ISNUMBER(SEARCH("Invalid Shipping Record",AD13)),ISNUMBER(SEARCH("Sales Mismatch",AD13)),ISNUMBER(SEARCH("Profit Mismatch",AD13)),ISNUMBER(SEARCH("Duplicate Order ID Conflict",AD13)),ISNUMBER(SEARCH("Missing Order Date",AD13)),ISNUMBER(SEARCH("Missing Ship Date",AD13))),"Invalid",IF(AD13<>"","Warning","Clean")) -> Clean
... A33: ORD-2025-10032 | B33: 45823 | C33: 45827 | D33: CUST-7867 | E33: =PROPER(TRIM(SUBSTITUTE(Raw_Text_Fields!B34,CHAR(160)," "))) -> Karan Malhotra | F33: =PROPER(TRIM(SUBSTITUTE(Raw_Text_Fields!C34,CHAR(160)," "))) -> Small Business | G33: =PROPER(TRIM(SUBSTITUTE(Raw_Text_Fields!D34,CHAR(160)," "))) -> West | H33: =PROPER(TRIM(SUBSTITUTE(Raw_Text_Fields!E34,CHAR(160)," "))) -> Madhya Pradesh | I33: =PROPER(TRIM(SUBSTITUTE(Raw_Text_Fields!F34,CHAR(160)," "))) -> Indore | J33: =PROPER(TRIM(SUBSTITUTE(Raw_Text_Fields!G34,CHAR(160)," "))) -> Office Supplies | K33: =PROPER(TRIM(SUBSTITUTE(Raw_Text_Fields!H34,CHAR(160)," "))) -> Paper | L33: Pro Paper 959 | M33: =PROPER(TRIM(SUBSTITUTE(Raw_Text_Fields!I34,CHAR(160)," "))) -> Second Class | N33: 9 | O33: 3092.55 | P33: 0 | Q33: 27832.95 | R33: 17769.75 | S33: 10063.2 | T33: =PROPER(TRIM(SUBSTITUTE(Raw_Text_Fields!J34,CHAR(160)," "))) -> Failed | U33: =PROPER(TRIM(SUBSTITUTE(Raw_Text_Fields!K34,CHAR(160)," "))) -> Returned | V33: =IF(OR(P33<0,P33>0.5),0,P33) -> 0 | W33: =N33*O33*(1-V33) -> 27832.95 | X33: =W33-R33 -> 10063.2 | Y33: =IFERROR(X33/W33,0) -> 0.36155708 | Z33: =C33-B33 -> 4 | AA33: =IF(B33="","",TEXT(B33,"mmm")) -> Jun | AB33: =IF(B33="","",YEAR(B33)) -> 2025 | AD33: =IF(LEFT(AC33&IF(B33="","; Missing Order Date","")&IF(C33="","; Missing Ship Date","")&IF(P33<0,"; Invalid Discount (Negative)","")&IF(P33>0.5,"; Invalid Discount (Too High)","")&IF(Z33<0,"; Invalid Shipping Record (Ship Before Order)","")&IF(ABS(Q33-W33)>1,"; Sales Mismatch","")&IF(ABS(S33-X33)>1,"; Profit Mismatch","")&IF(COUNTIF($A$2:$A$913,A33)>1,"; Duplicate Order ID Conflict",""),2)="; ",MID(AC33&IF(B33="","; Missing Order Date","")&IF(C33="","; Missing Ship Date","")&IF(P33<0,"; Invalid Discount (Negative)","")&IF(P33>0.5,"; Invalid Discount (Too High)","")&IF(Z33<0,"; Invalid Shipping Record (Ship Before Order)","")&IF(ABS(Q33-W33)>1,"; Sales Mismatch","")&IF(ABS(S33-X33)>1,"; Profit Mismatch","")&IF(COUNTIF($A$2:$A$913,A33)>1,"; Duplicate Order ID Conflict",""),3,500),AC33&IF(B33="","; Missing Order Date","")&IF(C33="","; Missing Ship Date","")&IF(P33<0,"; Invalid Discount (Negative)","")&IF(P33>0.5,"; Invalid Discount (Too High)","")&IF(Z33<0,"; Invalid Shipping Record (Ship Before Order)","")&IF(ABS(Q33-W33)>1,"; Sales Mismatch","")&IF(ABS(S33-X33)>1,"; Profit Mismatch","")&IF(COUNTIF($A$2:$A$913,A33)>1,"; Duplicate Order ID Conflict","")) | AE33: =IF(OR(ISNUMBER(SEARCH("Invalid Discount",AD33)),ISNUMBER(SEARCH("Invalid Shipping Record",AD33)),ISNUMBER(SEARCH("Sales Mismatch",AD33)),ISNUMBER(SEARCH("Profit Mismatch",AD33)),ISNUMBER(SEARCH("Duplicate Order ID Conflict",AD33)),ISNUMBER(SEARCH("Missing Order Date",AD33)),ISNUMBER(SEARCH("Missing Ship Date",AD33))),"Invalid",IF(AD33<>"","Warning","Clean")) -> Clean
A34: ORD-2024-10033 | B34: 45618 | C34: 45622 | D34: CUST-6509 | E34: =PROPER(TRIM(SUBSTITUTE(Raw_Text_Fields!B35,CHAR(160)," "))) -> Aarav Sharma | F34: =PROPER(TRIM(SUBSTITUTE(Raw_Text_Fields!C35,CHAR(160)," "))) -> Corporate | G34: =PROPER(TRIM(SUBSTITUTE(Raw_Text_Fields!D35,CHAR(160)," "))) -> South | H34: =PROPER(TRIM(SUBSTITUTE(Raw_Text_Fields!E35,CHAR(160)," "))) -> Andhra Pradesh | I34: =PROPER(TRIM(SUBSTITUTE(Raw_Text_Fields!F35,CHAR(160)," "))) -> Vijayawada | J34: =PROPER(TRIM(SUBSTITUTE(Raw_Text_Fields!G35,CHAR(160)," "))) -> Technology | K34: =PROPER(TRIM(SUBSTITUTE(Raw_Text_Fields!H35,CHAR(160)," "))) -> Phones | L34: Basic Phones 242 | M34: =PROPER(TRIM(SUBSTITUTE(Raw_Text_Fields!I35,CHAR(160)," "))) -> Second Class | N34: 3 | O34: 4001.25 | P34: 0 | Q34: 9002.81 | R34: 7529.92 | S34: 1472.89 | T34: =PROPER(TRIM(SUBSTITUTE(Raw_Text_Fields!J35,CHAR(160)," "))) -> Paid | U34: =PROPER(TRIM(SUBSTITUTE(Raw_Text_Fields!K35,CHAR(160)," "))) -> Completed | V34: =IF(OR(P34<0,P34>0.5),0,P34) -> 0 | W34: =N34*O34*(1-V34) -> 12003.75 | X34: =W34-R34 -> 4473.83 | Y34: =IFERROR(X34/W34,0) -> 0.3727027 | Z34: =C34-B34 -> 4 | AA34: =IF(B34="","",TEXT(B34,"mmm")) -> Nov | AB34: =IF(B34="","",YEAR(B34)) -> 2024 | AC34: Missing Discount (defaulted 0) | AD34: =IF(LEFT(AC34&IF(B34="","; Missing Order Date","")&IF(C34="","; Missing Ship Date","")&IF(P34<0,"; Invalid Discount (Negative)","")&IF(P34>0.5,"; Invalid Discount (Too High)","")&IF(Z34<0,"; Invalid Shipping Record (Ship Before Order)","")&IF(ABS(Q34-W34)>1,"; Sales Mismatch","")&IF(ABS(S34-X34)>1,"; Profit Mismatch","")&IF(COUNTIF($A$2:$A$913,A34)>1,"; Duplicate Order ID Conflict",""),2)="; ",MID(AC34&IF(B34="","; Missing Order Date","")&IF(C34="","; Missing Ship Date","")&IF(P34<0,"; Invalid Discount (Negative)","")&IF(P34>0.5,"; Invalid Discount (Too High)","")&IF(Z34<0,"; Invalid Shipping Record (Ship Before Order)","")&IF(ABS(Q34-W34)>1,"; Sales Mismatch","")&IF(ABS(S34-X34)>1,"; Profit Mismatch","")&IF(COUNTIF($A$2:$A$913,A34)>1,"; Duplicate Order ID Conflict",""),3,500),AC34&IF(B34="","; Missing Order Date","")&IF(C34="","; Missing Ship Date","")&IF(P34<0,"; Invalid Discount (Negative)","")&IF(P34>0.5,"; Invalid Discount (Too High)","")&IF(Z34<0,"; Invalid Shipping Record (Ship Before Order)","")&IF(ABS(Q34-W34)>1,"; Sales Mismatch","")&IF(ABS(S34-X34)>1,"; Profit Mismatch","")&IF(COUNTIF($A$2:$A$913,A34)>1,"; Duplicate Order ID Conflict","")) -> Missing Discount (defaulted 0); Sales Mismatch; Profit Mismatch | AE34: =IF(OR(ISNUMBER(SEARCH("Invalid Discount",AD34)),ISNUMBER(SEARCH("Invalid Shipping Record",AD34)),ISNUMBER(SEARCH("Sales Mismatch",AD34)),ISNUMBER(SEARCH("Profit Mismatch",AD34)),ISNUMBER(SEARCH("Duplicate Order ID Conflict",AD34)),ISNUMBER(SEARCH("Missing Order Date",AD34)),ISNUMBER(SEARCH("Missing Ship Date",AD34))),"Invalid",IF(AD34<>"","Warning","Clean")) -> Invalid
A35: ORD-2024-10034 | B35: 45495 | C35: 45500 | D35: CUST-6660 | E35: =PROPER(TRIM(SUBSTITUTE(Raw_Text_Fields!B36,CHAR(160)," "))) -> Priya Menon | F35: =PROPER(TRIM(SUBSTITUTE(Raw_Text_Fields!C36,CHAR(160)," "))) -> Home Office | G35: =PROPER(TRIM(SUBSTITUTE(Raw_Text_Fields!D36,CHAR(160)," "))) -> West | H35: =PROPER(TRIM(SUBSTITUTE(Raw_Text_Fields!E36,CHAR(160)," "))) -> Goa | I35: =PROPER(TRIM(SUBSTITUTE(Raw_Text_Fields!F36,CHAR(160)," "))) -> Panaji | J35: =PROPER(TRIM(SUBSTITUTE(Raw_Text_Fields!G36,CHAR(160)," "))) -> Furniture | K35: =PROPER(TRIM(SUBSTITUTE(Raw_Text_Fields!H36,CHAR(160)," "))) -> Tables | L35: Max Tables 836 | M35: =PROPER(TRIM(SUBSTITUTE(Raw_Text_Fields!I36,CHAR(160)," "))) -> Same Day | N35: 7 | O35: 492.41 | P35: 0.25 | Q35: 2585.15 | R35: 2070.73 | S35: 514.42 | T35: =PROPER(TRIM(SUBSTITUTE(Raw_Text_Fields!J36,CHAR(160)," "))) -> Paid | U35: =PROPER(TRIM(SUBSTITUTE(Raw_Text_Fields!K36,CHAR(160)," "))) -> Completed | V35: =IF(OR(P35<0,P35>0.5),0,P35) -> 0.25 | W35: =N35*O35*(1-V35) -> 2585.1525 | X35: =W35-R35 -> 514.4225 | Y35: =IFERROR(X35/W35,0) -> 0.19899116 | Z35: =C35-B35 -> 5 | AA35: =IF(B35="","",TEXT(B35,"mmm")) -> Jul | AB35: =IF(B35="","",YEAR(B35)) -> 2024 | AD35: =IF(LEFT(AC35&IF(B35="","; Missing Order Date","")&IF(C35="","; Missing Ship Date","")&IF(P35<0,"; Invalid Discount (Negative)","")&IF(P35>0.5,"; Invalid Discount (Too High)","")&IF(Z35<0,"; Invalid Shipping Record (Ship Before Order)","")&IF(ABS(Q35-W35)>1,"; Sales Mismatch","")&IF(ABS(S35-X35)>1,"; Profit Mismatch","")&IF(COUNTIF($A$2:$A$913,A35)>1,"; Duplicate Order ID Conflict",""),2)="; ",MID(AC35&IF(B35="","; Missing Order Date","")&IF(C35="","; Missing Ship Date","")&IF(P35<0,"; Invalid Discount (Negative)","")&IF(P35>0.5,"; Invalid Discount (Too High)","")&IF(Z35<0,"; Invalid Shipping Record (Ship Before Order)","")&IF(ABS(Q35-W35)>1,"; Sales Mismatch","")&IF(ABS(S35-X35)>1,"; Profit Mismatch","")&IF(COUNTIF($A$2:$A$913,A35)>1,"; Duplicate Order ID Conflict",""),3,500),AC35&IF(B35="","; Missing Order Date","")&IF(C35="","; Missing Ship Date","")&IF(P35<0,"; Invalid Discount (Negative)","")&IF(P35>0.5,"; Invalid Discount (Too High)","")&IF(Z35<0,"; Invalid Shipping Record (Ship Before Order)","")&IF(ABS(Q35-W35)>1,"; Sales Mismatch","")&IF(ABS(S35-X35)>1,"; Profit Mismatch","")&IF(COUNTIF($A$2:$A$913,A35)>1,"; Duplicate Order ID Conflict","")) | AE35: =IF(OR(ISNUMBER(SEARCH("Invalid Discount",AD35)),ISNUMBER(SEARCH("Invalid Shipping Record",AD35)),ISNUMBER(SEARCH("Sales Mismatch",AD35)),ISNUMBER(SEARCH("Profit Mismatch",AD35)),ISNUMBER(SEARCH("Duplicate Order ID Conflict",AD35)),ISNUMBER(SEARCH("Missing Order Date",AD35)),ISNUMBER(SEARCH("Missing Ship Date",AD35))),"Invalid",IF(AD35<>"","Warning","Clean")) -> Clean
A36: ORD-2025-10035 | B36: 45688 | C36: 45693 | D36: CUST-2392 | E36: =PROPER(TRIM(SUBSTITUTE(Raw_Text_Fields!B37,CHAR(160)," "))) -> Priya Menon | F36: =PROPER(TRIM(SUBSTITUTE(Raw_Text_Fields!C37,CHAR(160)," "))) -> Home Office | G36: =PROPER(TRIM(SUBSTITUTE(Raw_Text_Fields!D37,CHAR(160)," "))) -> East | H36: =PROPER(TRIM(SUBSTITUTE(Raw_Text_Fields!E37,CHAR(160)," "))) -> West Bengal | I36: =PROPER(TRIM(SUBSTITUTE(Raw_Text_Fields!F37,CHAR(160)," "))) -> Kolkata | J36: =PROPER(TRIM(SUBSTITUTE(Raw_Text_Fields!G37,CHAR(160)," "))) -> Furniture | K36: =PROPER(TRIM(SUBSTITUTE(Raw_Text_Fields!H37,CHAR(160)," "))) -> Chairs | L36: Elite Chairs 862 | M36: =PROPER(TRIM(SUBSTITUTE(Raw_Text_Fields!I37,CHAR(160)," "))) -> Unknown | N36: 2 | O36: 4159.69 | P36: 0.2 | Q36: 6655.5 | R36: 4340.21 | S36: 2607.32 | T36: =PROPER(TRIM(SUBSTITUTE(Raw_Text_Fields!J37,CHAR(160)," "))) -> Paid | U36: =PROPER(TRIM(SUBSTITUTE(Raw_Text_Fields!K37,CHAR(160)," "))) -> Completed | V36: =IF(OR(P36<0,P36>0.5),0,P36) -> 0.2 | W36: =N36*O36*(1-V36) -> 6655.504 | X36: =W36-R36 -> 2315.294 | Y36: =IFERROR(X36/W36,0) -> 0.34787658 | Z36: =C36-B36 -> 5 | AA36: =IF(B36="","",TEXT(B36,"mmm")) -> Jan | AB36: =IF(B36="","",YEAR(B36)) -> 2025 | AC36: Missing Ship Mode (filled Unknown) | AD36: =IF(LEFT(AC36&IF(B36="","; Missing Order Date","")&IF(C36="","; Missing Ship Date","")&IF(P36<0,"; Invalid Discount (Negative)","")&IF(P36>0.5,"; Invalid Discount (Too High)","")&IF(Z36<0,"; Invalid Shipping Record (Ship Before Order)","")&IF(ABS(Q36-W36)>1,"; Sales Mismatch","")&IF(ABS(S36-X36)>1,"; Profit Mismatch","")&IF(COUNTIF($A$2:$A$913,A36)>1,"; Duplicate Order ID Conflict",""),2)="; ",MID(AC36&IF(B36="","; Missing Order Date","")&IF(C36="","; Missing Ship Date","")&IF(P36<0,"; Invalid Discount (Negative)","")&IF(P36>0.5,"; Invalid Discount (Too High)","")&IF(Z36<0,"; Invalid Shipping Record (Ship Before Order)","")&IF(ABS(Q36-W36)>1,"; Sales Mismatch","")&IF(ABS(S36-X36)>1,"; Profit Mismatch","")&IF(COUNTIF($A$2:$A$913,A36)>1,"; Duplicate Order ID Conflict",""),3,500),AC36&IF(B36="","; Missing Order Date","")&IF(C36="","; Missing Ship Date","")&IF(P36<0,"; Invalid Discount (Negative)","")&IF(P36>0.5,"; Invalid Discount (Too High)","")&IF(Z36<0,"; Invalid Shipping Record (Ship Before Order)","")&IF(ABS(Q36-W36)>1,"; Sales Mismatch","")&IF(ABS(S36-X36)>1,"; Profit Mismatch","")&IF(COUNTIF($A$2:$A$913,A36)>1,"; Duplicate Order ID Conflict","")) -> Missing Ship Mode (filled Unknown); Profit Mismatch | AE36: =IF(OR(ISNUMBER(SEARCH("Invalid Discount",AD36)),ISNUMBER(SEARCH("Invalid Shipping Record",AD36)),ISNUMBER(SEARCH("Sales Mismatch",AD36)),ISNUMBER(SEARCH("Profit Mismatch",AD36)),ISNUMBER(SEARCH("Duplicate Order ID Conflict",AD36)),ISNUMBER(SEARCH("Missing Order Date",AD36)),ISNUMBER(SEARCH("Missing Ship Date",AD36))),"Invalid",IF(AD36<>"","Warning","Clean")) -> Invalid
A37: ORD-2024-10036 | B37: 45441 | C37: 45441 | D37: CUST-1611 | E37: =PROPER(TRIM(SUBSTITUTE(Raw_Text_Fields!B38,CHAR(160)," "))) -> Sneha Kapoor | F37: =PROPER(TRIM(SUBSTITUTE(Raw_Text_Fields!C38,CHAR(160)," "))) -> Small Business | G37: =PROPER(TRIM(SUBSTITUTE(Raw_Text_Fields!D38,CHAR(160)," "))) -> West | H37: =PROPER(TRIM(SUBSTITUTE(Raw_Text_Fields!E38,CHAR(160)," "))) -> Gujarat | I37: =PROPER(TRIM(SUBSTITUTE(Raw_Text_Fields!F38,CHAR(160)," "))) -> Ahmedabad | J37: =PROPER(TRIM(SUBSTITUTE(Raw_Text_Fields!G38,CHAR(160)," "))) -> Furniture | K37: =PROPER(TRIM(SUBSTITUTE(Raw_Text_Fields!H38,CHAR(160)," "))) -> Bookcases | L37: Prime Bookcases 414 | M37: =PROPER(TRIM(SUBSTITUTE(Raw_Text_Fields!I38,CHAR(160)," "))) -> Second Class | N37: 8 | O37: 2507.12 | P37: 0.05 | Q37: 19054.11 | R37: 15313.83 | S37: 3740.28 | T37: =PROPER(TRIM(SUBSTITUTE(Raw_Text_Fields!J38,CHAR(160)," "))) -> Pending | U37: =PROPER(TRIM(SUBSTITUTE(Raw_Text_Fields!K38,CHAR(160)," "))) -> Returned | V37: =IF(OR(P37<0,P37>0.5),0,P37) -> 0.05 | W37: =N37*O37*(1-V37) -> 19054.112 | X37: =W37-R37 -> 3740.282 | Y37: =IFERROR(X37/W37,0) -> 0.19629789 | Z37: =C37-B37 -> 0 | AA37: =IF(B37="","",TEXT(B37,"mmm")) -> May | AB37: =IF(B37="","",YEAR(B37)) -> 2024 | AD37: =IF(LEFT(AC37&IF(B37="","; Missing Order Date","")&IF(C37="","; Missing Ship Date","")&IF(P37<0,"; Invalid Discount (Negative)","")&IF(P37>0.5,"; Invalid Discount (Too High)","")&IF(Z37<0,"; Invalid Shipping Record (Ship Before Order)","")&IF(ABS(Q37-W37)>1,"; Sales Mismatch","")&IF(ABS(S37-X37)>1,"; Profit Mismatch","")&IF(COUNTIF($A$2:$A$913,A37)>1,"; Duplicate Order ID Conflict",""),2)="; ",MID(AC37&IF(B37="","; Missing Order Date","")&IF(C37="","; Missing Ship Date","")&IF(P37<0,"; Invalid Discount (Negative)","")&IF(P37>0.5,"; Invalid Discount (Too High)","")&IF(Z37<0,"; Invalid Shipping Record (Ship Before Order)","")&IF(ABS(Q37-W37)>1,"; Sales Mismatch","")&IF(ABS(S37-X37)>1,"; Profit Mismatch","")&IF(COUNTIF($A$2:$A$913,A37)>1,"; Duplicate Order ID Conflict",""),3,500),AC37&IF(B37="","; Missing Order Date","")&IF(C37="","; Missing Ship Date","")&IF(P37<0,"; Invalid Discount (Negative)","")&IF(P37>0.5,"; Invalid Discount (Too High)","")&IF(Z37<0,"; Invalid Shipping Record (Ship Before Order)","")&IF(ABS(Q37-W37)>1,"; Sales Mismatch","")&IF(ABS(S37-X37)>1,"; Profit Mismatch","")&IF(COUNTIF($A$2:$A$913,A37)>1,"; Duplicate Order ID Conflict","")) | AE37: =IF(OR(ISNUMBER(SEARCH("Invalid Discount",AD37)),ISNUMBER(SEARCH("Invalid Shipping Record",AD37)),ISNUMBER(SEARCH("Sales Mismatch",AD37)),ISNUMBER(SEARCH("Profit Mismatch",AD37)),ISNUMBER(SEARCH("Duplicate Order ID Conflict",AD37)),ISNUMBER(SEARCH("Missing Order Date",AD37)),ISNUMBER(SEARCH("Missing Ship Date",AD37))),"Invalid",IF(AD37<>"","Warning","Clean")) -> Clean
A38: ORD-2024-10037 | B38: 45590 | C38: 45593 | D38: CUST-8296 | E38: =PROPER(TRIM(SUBSTITUTE(Raw_Text_Fields!B39,CHAR(160)," "))) -> Rohan Mehta | F38: =PROPER(TRIM(SUBSTITUTE(Raw_Text_Fields!C39,CHAR(160)," "))) -> Corporate | G38: =PROPER(TRIM(SUBSTITUTE(Raw_Text_Fields!D39,CHAR(160)," "))) -> West | H38: =PROPER(TRIM(SUBSTITUTE(Raw_Text_Fields!E39,CHAR(160)," "))) -> Maharashtra | I38: =PROPER(TRIM(SUBSTITUTE(Raw_Text_Fields!F39,CHAR(160)," "))) -> Mumbai | J38: =PROPER(TRIM(SUBSTITUTE(Raw_Text_Fields!G39,CHAR(160)," "))) -> Furniture | K38: =PROPER(TRIM(SUBSTITUTE(Raw_Text_Fields!H39,CHAR(160)," "))) -> Bookcases | L38: Eco Bookcases 220 | M38: =PROPER(TRIM(SUBSTITUTE(Raw_Text_Fields!I39,CHAR(160)," "))) -> Second Class | N38: 3 | O38: 3126.47 | P38: 0 | Q38: 9379.41 | R38: 6670.85 | S38: 2708.56 | T38: =PROPER(TRIM(SUBSTITUTE(Raw_Text_Fields!J39,CHAR(160)," "))) -> Paid | U38: =PROPER(TRIM(SUBSTITUTE(Raw_Text_Fields!K39,CHAR(160)," "))) -> Returned | V38: =IF(OR(P38<0,P38>0.5),0,P38) -> 0 | W38: =N38*O38*(1-V38) -> 9379.41 | X38: =W38-R38 -> 2708.56 | Y38: =IFERROR(X38/W38,0) -> 0.28877723 | Z38: =C38-B38 -> 3 | AA38: =IF(B38="","",TEXT(B38,"mmm")) -> Oct | AB38: =IF(B38="","",YEAR(B38)) -> 2024 | AD38: =IF(LEFT(AC38&IF(B38="","; Missing Order Date","")&IF(C38="","; Missing Ship Date","")&IF(P38<0,"; Invalid Discount (Negative)","")&IF(P38>0.5,"; Invalid Discount (Too High)","")&IF(Z38<0,"; Invalid Shipping Record (Ship Before Order)","")&IF(ABS(Q38-W38)>1,"; Sales Mismatch","")&IF(ABS(S38-X38)>1,"; Profit Mismatch","")&IF(COUNTIF($A$2:$A$913,A38)>1,"; Duplicate Order ID Conflict",""),2)="; ",MID(AC38&IF(B38="","; Missing Order Date","")&IF(C38="","; Missing Ship Date","")&IF(P38<0,"; Invalid Discount (Negative)","")&IF(P38>0.5,"; Invalid Discount (Too High)","")&IF(Z38<0,"; Invalid Shipping Record (Ship Before Order)","")&IF(ABS(Q38-W38)>1,"; Sales Mismatch","")&IF(ABS(S38-X38)>1,"; Profit Mismatch","")&IF(COUNTIF($A$2:$A$913,A38)>1,"; Duplicate Order ID Conflict",""),3,500),AC38&IF(B38="","; Missing Order Date","")&IF(C38="","; Missing Ship Date","")&IF(P38<0,"; Invalid Discount (Negative)","")&IF(P38>0.5,"; Invalid Discount (Too High)","")&IF(Z38<0,"; Invalid Shipping Record (Ship Before Order)","")&IF(ABS(Q38-W38)>1,"; Sales Mismatch","")&IF(ABS(S38-X38)>1,"; Profit Mismatch","")&IF(COUNTIF($A$2:$A$913,A38)>1,"; Duplicate Order ID Conflict","")) | AE38: =IF(OR(ISNUMBER(SEARCH("Invalid Discount",AD38)),ISNUMBER(SEARCH("Invalid Shipping Record",AD38)),ISNUMBER(SEARCH("Sales Mismatch",AD38)),ISNUMBER(SEARCH("Profit Mismatch",AD38)),ISNUMBER(SEARCH("Duplicate Order ID Conflict",AD38)),ISNUMBER(SEARCH("Missing Order Date",AD38)),ISNUMBER(SEARCH("Missing Ship Date",AD38))),"Invalid",IF(AD38<>"","Warning","Clean")) -> Clean
A39: ORD-2025-10038 | B39: 45867 | C39: 45867 | D39: CUST-4646 | E39: =PROPER(TRIM(SUBSTITUTE(Raw_Text_Fields!B40,CHAR(160)," "))) -> Diya Patel | F39: =PROPER(TRIM(SUBSTITUTE(Raw_Text_Fields!C40,CHAR(160)," "))) -> Consumer | G39: =PROPER(TRIM(SUBSTITUTE(Raw_Text_Fields!D40,CHAR(160)," "))) -> West | H39: =PROPER(TRIM(SUBSTITUTE(Raw_Text_Fields!E40,CHAR(160)," "))) -> Maharashtra | I39: =PROPER(TRIM(SUBSTITUTE(Raw_Text_Fields!F40,CHAR(160)," "))) -> Mumbai | J39: =PROPER(TRIM(SUBSTITUTE(Raw_Text_Fields!G40,CHAR(160)," "))) -> Technology | K39: =PROPER(TRIM(SUBSTITUTE(Raw_Text_Fields!H40,CHAR(160)," "))) -> Copiers | L39: Pro Copiers 830 | M39: =PROPER(TRIM(SUBSTITUTE(Raw_Text_Fields!I40,CHAR(160)," "))) -> Standard Class | N39: 4 | O39: 1327.54 | P39: 0.2 | Q39: 4248.13 | R39: 3321.09 | S39: 927.04 | T39: =PROPER(TRIM(SUBSTITUTE(Raw_Text_Fields!J40,CHAR(160)," "))) -> Paid | U39: =PROPER(TRIM(SUBSTITUTE(Raw_Text_Fields!K40,CHAR(160)," "))) -> Completed | V39: =IF(OR(P39<0,P39>0.5),0,P39) -> 0.2 | W39: =N39*O39*(1-V39) -> 4248.128 | X39: =W39-R39 -> 927.038 | Y39: =IFERROR(X39/W39,0) -> 0.21822271 | Z39: =C39-B39 -> 0 | AA39: =IF(B39="","",TEXT(B39,"mmm")) -> Jul | AB39: =IF(B39="","",YEAR(B39)) -> 2025 | AD39: =IF(LEFT(AC39&IF(B39="","; Missing Order Date","")&IF(C39="","; Missing Ship Date","")&IF(P39<0,"; Invalid Discount (Negative)","")&IF(P39>0.5,"; Invalid Discount (Too High)","")&IF(Z39<0,"; Invalid Shipping Record (Ship Before Order)","")&IF(ABS(Q39-W39)>1,"; Sales Mismatch","")&IF(ABS(S39-X39)>1,"; Profit Mismatch","")&IF(COUNTIF($A$2:$A$913,A39)>1,"; Duplicate Order ID Conflict",""),2)="; ",MID(AC39&IF(B39="","; Missing Order Date","")&IF(C39="","; Missing Ship Date","")&IF(P39<0,"; Invalid Discount (Negative)","")&IF(P39>0.5,"; Invalid Discount (Too High)","")&IF(Z39<0,"; Invalid Shipping Record (Ship Before Order)","")&IF(ABS(Q39-W39)>1,"; Sales Mismatch","")&IF(ABS(S39-X39)>1,"; Profit Mismatch","")&IF(COUNTIF($A$2:$A$913,A39)>1,"; Duplicate Order ID Conflict",""),3,500),AC39&IF(B39="","; Missing Order Date","")&IF(C39="","; Missing Ship Date","")&IF(P39<0,"; Invalid Discount (Negative)","")&IF(P39>0.5,"; Invalid Discount (Too High)","")&IF(Z39<0,"; Invalid Shipping Record (Ship Before Order)","")&IF(ABS(Q39-W39)>1,"; Sales Mismatch","")&IF(ABS(S39-X39)>1,"; Profit Mismatch","")&IF(COUNTIF($A$2:$A$913,A39)>1,"; Duplicate Order ID Conflict","")) | AE39: =IF(OR(ISNUMBER(SEARCH("Invalid Discount",AD39)),ISNUMBER(SEARCH("Invalid Shipping Record",AD39)),ISNUMBER(SEARCH("Sales Mismatch",AD39)),ISNUMBER(SEARCH("Profit Mismatch",AD39)),ISNUMBER(SEARCH("Duplicate Order ID Conflict",AD39)),ISNUMBER(SEARCH("Missing Order Date",AD39)),ISNUMBER(SEARCH("Missing Ship Date",AD39))),"Invalid",IF(AD39<>"","Warning","Clean")) -> Clean
A40: ORD-2024-10039 | B40: 45460 | C40: 45465 | D40: CUST-8235 | E40: =PROPER(TRIM(SUBSTITUTE(Raw_Text_Fields!B41,CHAR(160)," "))) -> Aarav Sharma | F40: =PROPER(TRIM(SUBSTITUTE(Raw_Text_Fields!C41,CHAR(160)," "))) -> Corporate | G40: =PROPER(TRIM(SUBSTITUTE(Raw_Text_Fields!D41,CHAR(160)," "))) -> West | H40: =PROPER(TRIM(SUBSTITUTE(Raw_Text_Fields!E41,CHAR(160)," "))) -> Gujarat | I40: =PROPER(TRIM(SUBSTITUTE(Raw_Text_Fields!F41,CHAR(160)," "))) -> Ahmedabad | J40: =PROPER(TRIM(SUBSTITUTE(Raw_Text_Fields!G41,CHAR(160)," "))) -> Technology | K40: =PROPER(TRIM(SUBSTITUTE(Raw_Text_Fields!H41,CHAR(160)," "))) -> Phones | L40: Prime Phones 507 | M40: =PROPER(TRIM(SUBSTITUTE(Raw_Text_Fields!I41,CHAR(160)," "))) -> First Class | N40: 7 | O40: 2210.68 | P40: 0.1 | Q40: 13927.28 | R40: 10504.87 | S40: 3422.41 | T40: =PROPER(TRIM(SUBSTITUTE(Raw_Text_Fields!J41,CHAR(160)," "))) -> Paid | U40: =PROPER(TRIM(SUBSTITUTE(Raw_Text_Fields!K41,CHAR(160)," "))) -> Completed | V40: =IF(OR(P40<0,P40>0.5),0,P40) -> 0.1 | W40: =N40*O40*(1-V40) -> 13927.284 | X40: =W40-R40 -> 3422.414 | Y40: =IFERROR(X40/W40,0) -> 0.24573449 | Z40: =C40-B40 -> 5 | AA40: =IF(B40="","",TEXT(B40,"mmm")) -> Jun | AB40: =IF(B40="","",YEAR(B40)) -> 2024 | AD40: =IF(LEFT(AC40&IF(B40="","; Missing Order Date","")&IF(C40="","; Missing Ship Date","")&IF(P40<0,"; Invalid Discount (Negative)","")&IF(P40>0.5,"; Invalid Discount (Too High)","")&IF(Z40<0,"; Invalid Shipping Record (Ship Before Order)","")&IF(ABS(Q40-W40)>1,"; Sales Mismatch","")&IF(ABS(S40-X40)>1,"; Profit Mismatch","")&IF(COUNTIF($A$2:$A$913,A40)>1,"; Duplicate Order ID Conflict",""),2)="; ",MID(AC40&IF(B40="","; Missing Order Date","")&IF(C40="","; Missing Ship Date","")&IF(P40<0,"; Invalid Discount (Negative)","")&IF(P40>0.5,"; Invalid Discount (Too High)","")&IF(Z40<0,"; Invalid Shipping Record (Ship Before Order)","")&IF(ABS(Q40-W40)>1,"; Sales Mismatch","")&IF(ABS(S40-X40)>1,"; Profit Mismatch","")&IF(COUNTIF($A$2:$A$913,A40)>1,"; Duplicate Order ID Conflict",""),3,500),AC40&IF(B40="","; Missing Order Date","")&IF(C40="","; Missing Ship Date","")&IF(P40<0,"; Invalid Discount (Negative)","")&IF(P40>0.5,"; Invalid Discount (Too High)","")&IF(Z40<0,"; Invalid Shipping Record (Ship Before Order)","")&IF(ABS(Q40-W40)>1,"; Sales Mismatch","")&IF(ABS(S40-X40)>1,"; Profit Mismatch","")&IF(COUNTIF($A$2:$A$913,A40)>1,"; Duplicate Order ID Conflict","")) | AE40: =IF(OR(ISNUMBER(SEARCH("Invalid Discount",AD40)),ISNUMBER(SEARCH("Invalid Shipping Record",AD40)),ISNUMBER(SEARCH("Sales Mismatch",AD40)),ISNUMBER(SEARCH("Profit Mismatch",AD40)),ISNUMBER(SEARCH("Duplicate Order ID Conflict",AD40)),ISNUMBER(SEARCH("Missing Order Date",AD40)),ISNUMBER(SEARCH("Missing Ship Date",AD40))),"Invalid",IF(AD40<>"","Warning","Clean")) -> Clean
A41: ORD-2024-10040 | B41: 45637 | C41: 45637 | D41: CUST-5830 | E41: =PROPER(TRIM(SUBSTITUTE(Raw_Text_Fields!B42,CHAR(160)," "))) -> Mira Das | F41: =PROPER(TRIM(SUBSTITUTE(Raw_Text_Fields!C42,CHAR(160)," "))) -> Small Business | G41: =PROPER(TRIM(SUBSTITUTE(Raw_Text_Fields!D42,CHAR(160)," "))) -> West | H41: =PROPER(TRIM(SUBSTITUTE(Raw_Text_Fields!E42,CHAR(160)," "))) -> Madhya Pradesh | I41: =PROPER(TRIM(SUBSTITUTE(Raw_Text_Fields!F42,CHAR(160)," "))) -> Indore | J41: =PROPER(TRIM(SUBSTITUTE(Raw_Text_Fields!G42,CHAR(160)," "))) -> Technology | K41: =PROPER(TRIM(SUBSTITUTE(Raw_Text_Fields!H42,CHAR(160)," "))) -> Copiers | L41: Classic Copiers 590 | M41: =PROPER(TRIM(SUBSTITUTE(Raw_Text_Fields!I42,CHAR(160)," "))) -> First Class | N41: 4 | O41: 1370.92 | P41: 0.1 | Q41: 4935.31 | R41: 3374.77 | S41: 1560.54 | T41: =PROPER(TRIM(SUBSTITUTE(Raw_Text_Fields!J42,CHAR(160)," "))) -> Pending | U41: =PROPER(TRIM(SUBSTITUTE(Raw_Text_Fields!K42,CHAR(160)," "))) -> Returned | V41: =IF(OR(P41<0,P41>0.5),0,P41) -> 0.1 | W41: =N41*O41*(1-V41) -> 4935.312 | X41: =W41-R41 -> 1560.542 | Y41: =IFERROR(X41/W41,0) -> 0.31619926 | Z41: =C41-B41 -> 0 | AA41: =IF(B41="","",TEXT(B41,"mmm")) -> Dec | AB41: =IF(B41="","",YEAR(B41)) -> 2024 | AD41: =IF(LEFT(AC41&IF(B41="","; Missing Order Date","")&IF(C41="","; Missing Ship Date","")&IF(P41<0,"; Invalid Discount (Negative)","")&IF(P41>0.5,"; Invalid Discount (Too High)","")&IF(Z41<0,"; Invalid Shipping Record (Ship Before Order)","")&IF(ABS(Q41-W41)>1,"; Sales Mismatch","")&IF(ABS(S41-X41)>1,"; Profit Mismatch","")&IF(COUNTIF($A$2:$A$913,A41)>1,"; Duplicate Order ID Conflict",""),2)="; ",MID(AC41&IF(B41="","; Missing Order Date","")&IF(C41="","; Missing Ship Date","")&IF(P41<0,"; Invalid Discount (Negative)","")&IF(P41>0.5,"; Invalid Discount (Too High)","")&IF(Z41<0,"; Invalid Shipping Record (Ship Before Order)","")&IF(ABS(Q41-W41)>1,"; Sales Mismatch","")&IF(ABS(S41-X41)>1,"; Profit Mismatch","")&IF(COUNTIF($A$2:$A$913,A41)>1,"; Duplicate Order ID Conflict",""),3,500),AC41&IF(B41="","; Missing Order Date","")&IF(C41="","; Missing Ship Date","")&IF(P41<0,"; Invalid Discount (Negative)","")&IF(P41>0.5,"; Invalid Discount (Too High)","")&IF(Z41<0,"; Invalid Shipping Record (Ship Before Order)","")&IF(ABS(Q41-W41)>1,"; Sales Mismatch","")&IF(ABS(S41-X41)>1,"; Profit Mismatch","")&IF(COUNTIF($A$2:$A$913,A41)>1,"; Duplicate Order ID Conflict","")) | AE41: =IF(OR(ISNUMBER(SEARCH("Invalid Discount",AD41)),ISNUMBER(SEARCH("Invalid Shipping Record",AD41)),ISNUMBER(SEARCH("Sales Mismatch",AD41)),ISNUMBER(SEARCH("Profit Mismatch",AD41)),ISNUMBER(SEARCH("Duplicate Order ID Conflict",AD41)),ISNUMBER(SEARCH("Missing Order Date",AD41)),ISNUMBER(SEARCH("Missing Ship Date",AD41))),"Invalid",IF(AD41<>"","Warning","Clean")) -> Clean
